Workbook

Sheet Market Analysis (2)
A1: TAM/SAM/SOM Market Analysis
A2: Analysis Date: July 03, 2025
A4: MARKET DEFINITION
A5: Market Category:
A6: Product/Service:
A7: Target Geography:
A8: Time Period:
A10: TOTAL ADDRESSABLE MARKET (TAM)
A11: Metric | B11: Value | C11: Unit | D11: Source | E11: Notes | F11: Confidence
A12: Total Market Size | C12: $B | E12: Global market size | F12: High
A13: Market Growth Rate | C13: % | E13: Annual growth rate | F13: Medium
A14: Number of Potential Users | C14: Million | E14: Total addressable users | F14: Medium
A15: Average Revenue per User | C15: $ | E15: ARPU calculation | F15: Medium
A16: Market Penetration Rate | C16: % | E16: Current penetration | F16: Low
A18: TAM Calculation: | B18: =B12*B14 -> 0 | C18: $B
A20: SERVICEABLE ADDRESSABLE MARKET (SAM)
A21: Metric | B21: Value | C21: Unit | D21: Source | E21: Notes | F21: Confidence
A22: Geographic Constraints | C22: % | E22: Geographic limitations | F22: High
A23: Regulatory Constraints | C23: % | E23: Regulatory barriers | F23: Medium
A24: Technology Constraints | C24: % | E24: Technology limitations | F24: Medium
A25: Customer Segment Focus | C25: % | E25: Target customer segments | F25: High
A26: Distribution Channel Access | C26: % | E26: Channel availability | F26: Medium
A28: SAM Calculation: | B28: =B18*B22*B23*B24*B25*B26/100^5 -> 0 | C28: $B
A30: SERVICEABLE OBTAINABLE MARKET (SOM)
A31: Metric | B31: Value | C31: Unit | D31: Source | E31: Notes | F31: Confidence
A32: Market Share Goal (Year 1) | C32: % | E32: Realistic market share | F32: High
A33: Market Share Goal (Year 3) | C33: % | E33: 3-year target | F33: Medium
A34: Market Share Goal (Year 5) | C34: % | E34: 5-year target | F34: Low
A35: Competitive Advantage | C35: Score 1-10 | E35: Competitive strength | F35: Medium
A36: Resource Constraints | C36: % | E36: Resource limitations | F36: High
A38: SOM Year 1: | B38: =B28*B32/100 -> 0 | C38: $B
A39: SOM Year 3: | B39: =B28*B33/100 -> 0 | C39: $B
A40: SOM Year 5: | B40: =B28*B34/100 -> 0 | C40: $B
A42: MARKET VALIDATION & ASSESSMENT
A44: Customer Validation
A45: Validation Metric | B45: Score (1-10) | C45: Weight | D45: Weighted Score | E45: Evidence/Source | F45: Action Required
A46: Customer Problem Validation | C46: 20% | D46: =B46*C46/100 -> 0 | E46: Customer interviews
A47: Solution-Market Fit | C47: 25% | D47: =B47*C47/100 -> 0 | E47: Product testing
A48: Willingness to Pay | C48: 20% | D48: =B48*C48/100 -> 0 | E48: Pricing surveys
A49: Customer Acquisition Cost | C49: 15% | D49: =B49*C49/100 -> 0 | E49: Marketing tests
...

Sheet Dashboard
A1: TAM/SAM/SOM Analysis Dashboard
A3: Key Market Metrics
A4: Metric | B4: Value | C4: Unit | D4: Confidence | E4: Notes
A5: TAM | B5: ='Market Analysis'!B18 -> 0 | C5: $B | D5: Medium | E5: Total Addressable Market
A6: SAM | B6: ='Market Analysis'!B28 -> 0 | C6: $B | D6: Medium | E6: Serviceable Addressable Market
A7: SOM (Year 1) | B7: ='Market Analysis'!B38 -> 0 | C7: $B | D7: High | E7: Serviceable Obtainable Market
A8: SOM (Year 3) | B8: ='Market Analysis'!B39 -> 0 | C8: $B | D8: Medium | E8: 3-Year Target
A9: SOM (Year 5) | B9: ='Market Analysis'!B40 -> 0 | C9: $B | D9: Low | E9: 5-Year Vision

Sheet Market Analysis
A1: TAM/SAM/SOM Market Analysis
A2: Analysis Date: July 03, 2025
A4: MARKET DEFINITION
A5: Market Category:
A6: Product/Service:
A7: Target Geography:
A8: Time Period:
A10: TOTAL ADDRESSABLE MARKET (TAM)
A11: Metric | B11: Value | C11: Unit | D11: Source | E11: Notes | F11: Confidence
A12: Total Market Size | C12: $B | E12: Global market size | F12: High
A13: Market Growth Rate | C13: % | E13: Annual growth rate | F13: Medium
A14: Number of Potential Users | C14: Million | E14: Total addressable users | F14: Medium
A15: Average Revenue per User | C15: $ | E15: ARPU calculation | F15: Medium
A16: Market Penetration Rate | C16: % | E16: Current penetration | F16: Low
A18: TAM Calculation: | B18: =B12*B14 -> 0 | C18: $B
A20: SERVICEABLE ADDRESSABLE MARKET (SAM)
A21: Metric | B21: Value | C21: Unit | D21: Source | E21: Notes | F21: Confidence
A22: Geographic Constraints | C22: % | E22: Geographic limitations | F22: High
A23: Regulatory Constraints | C23: % | E23: Regulatory barriers | F23: Medium
A24: Technology Constraints | C24: % | E24: Technology limitations | F24: Medium
A25: Customer Segment Focus | C25: % | E25: Target customer segments | F25: High
A26: Distribution Channel Access | C26: % | E26: Channel availability | F26: Medium
A28: SAM Calculation: | B28: =B18*B22*B23*B24*B25*B26/100^5 -> 0 | C28: $B
A30: SERVICEABLE OBTAINABLE MARKET (SOM)
A31: Metric | B31: Value | C31: Unit | D31: Source | E31: Notes | F31: Confidence
A32: Market Share Goal (Year 1) | C32: % | E32: Realistic market share | F32: High
A33: Market Share Goal (Year 3) | C33: % | E33: 3-year target | F33: Medium
A34: Market Share Goal (Year 5) | C34: % | E34: 5-year target | F34: Low
A35: Competitive Advantage | C35: Score 1-10 | E35: Competitive strength | F35: Medium
A36: Resource Constraints | C36: % | E36: Resource limitations | F36: High
A38: SOM Year 1: | B38: =B28*B32/100 -> 0 | C38: $B
A39: SOM Year 3: | B39: =B28*B33/100 -> 0 | C39: $B
A40: SOM Year 5: | B40: =B28*B34/100 -> 0 | C40: $B
A42: MARKET VALIDATION & ASSESSMENT
A44: Data Quality Assessment
A45: High Confidence Data Sources:
A46: Medium Confidence Data Sources:
A47: Low Confidence Data Sources:
A48: Overall Data Quality Rating: | B48: High/Medium/Low
A50: Key Assumptions Made
...
